Workbook

Sheet Property Types
A1: Main Type | B1: Subtype | C1: Slug | D1: Crexi Verified | E1: Crexi URL | F1: Notes
A2: Retail | B2: Retail (All) | C2: retail | D2: Yes | E2: https://www.crexi.com/properties/Retail | F2: Top-level Crexi category
A3: Retail | B3: Shopping Center | C3: shopping-centers | D3: Yes | E3: https://www.crexi.com/properties/Shopping-Centers | F3: Generic shopping center
A4: Retail | B4: Neighborhood Center | C4: neighborhood-center | D4: No | F4: Under shopping centers
A5: Retail | B5: Community Center | C5: community-center | D5: No | F5: Under shopping centers
A6: Retail | B6: Power Center | C6: power-center | D6: No | F6: Big-box anchored
A7: Retail | B7: Regional / Super-Regional Mall | C7: regional-mall | D7: No
A8: Retail | B8: Lifestyle Center | C8: lifestyle-center | D8: No
A9: Retail | B9: Outlet Center | C9: outlet-center | D9: No
A10: Retail | B10: Strip Center / Strip Mall | C10: strip-center | D10: No
A11: Retail | B11: Freestanding / Single-Tenant | C11: freestanding-retail | D11: No | F11: Often NNN
A12: Retail | B12: Restaurant / QSR | C12: restaurant | D12: No | F12: Quick-service restaurant
A13: Retail | B13: Bank | C13: bank | D13: No
A14: Retail | B14: Auto Dealership | C14: auto-dealership | D14: No
A15: Retail | B15: Convenience Store / C-Store | C15: convenience-store | D15: No
A16: Retail | B16: Pharmacy / Drugstore | C16: pharmacy | D16: No
A17: Retail | B17: Big Box / Anchor | C17: big-box | D17: No
A18: Retail | B18: Pad Site / Outparcel | C18: pad-site | D18: No
A19: Retail | B19: High Street / Storefront | C19: storefront | D19: No
A20: Office | B20: Office (All) | C20: office | D20: Yes | E20: https://www.crexi.com/properties/Office | F20: Top-level Crexi category
A21: Office | B21: Traditional Office Class A | C21: office-class-a | D21: No
A22: Office | B22: Traditional Office Class B | C22: office-class-b | D22: No
A23: Office | B23: Traditional Office Class C | C23: office-class-c | D23: No
A24: Office | B24: Medical Office Building (MOB) | C24: medical-office | D24: No
A25: Office | B25: Creative Office / Loft | C25: creative-office | D25: No
A26: Office | B26: Executive Suites / Coworking | C26: coworking | D26: No
A27: Office | B27: Professional / Dental | C27: professional-office | D27: No
A28: Office | B28: Office Condo | C28: office-condo | D28: No
A29: Office | B29: Government Office | C29: government-office | D29: No
A30: Office | B30: Office Campus | C30: office-campus | D30: No
A31: Industrial | B31: Industrial (All) | C31: industrial | D31: Yes | E31: https://www.crexi.com/properties/Industrial | F31: Top-level Crexi category
A32: Industrial | B32: Warehouse | C32: warehouses | D32: Yes | E32: https://www.crexi.com/properties/Warehouses | F32: Verified Crexi slug
A33: Industrial | B33: Distribution Center | C33: distribution-center | D33: No
A34: Industrial | B34: Manufacturing | C34: manufacturing | D34: No
A35: Industrial | B35: Flex / R&D | C35: industrial-flex | D35: Yes | E35: https://www.crexi.com/properties/Industrial-Flex | F35: Verified Crexi slug
A36: Industrial | B36: Light Industrial | C36: light-industrial | D36: No
A37: Industrial | B37: Heavy Industrial | C37: heavy-industrial | D37: No
A38: Industrial | B38: Refrigerated / Cold Storage | C38: refrigerated-and-cold-storage | D38: Yes | E38: https://www.crexi.com/properties/Refrigerated-and-Cold-Storage | F38: Verified Crexi slug
A39: Industrial | B39: Truck Terminal / Transportation | C39: truck-terminal | D39: No
A40: Industrial | B40: Data Center | C40: data-center | D40: No
...

Sheet Summary
A1: Main Type | B1: Subtype Count | C1: Crexi Verified Count
A2: Retail | B2: =COUNTIF('Property Types'!A:A,A2) | C2: =COUNTIFS('Property Types'!A:A,A2,'Property Types'!D:D,"Yes")
A3: Office | B3: =COUNTIF('Property Types'!A:A,A3) | C3: =COUNTIFS('Property Types'!A:A,A3,'Property Types'!D:D,"Yes")
A4: Industrial | B4: =COUNTIF('Property Types'!A:A,A4) | C4: =COUNTIFS('Property Types'!A:A,A4,'Property Types'!D:D,"Yes")
A5: Multifamily | B5: =COUNTIF('Property Types'!A:A,A5) | C5: =COUNTIFS('Property Types'!A:A,A5,'Property Types'!D:D,"Yes")
A6: Hospitality | B6: =COUNTIF('Property Types'!A:A,A6) | C6: =COUNTIFS('Property Types'!A:A,A6,'Property Types'!D:D,"Yes")
A7: Land | B7: =COUNTIF('Property Types'!A:A,A7) | C7: =COUNTIFS('Property Types'!A:A,A7,'Property Types'!D:D,"Yes")
A8: Mixed Use | B8: =COUNTIF('Property Types'!A:A,A8) | C8: =COUNTIFS('Property Types'!A:A,A8,'Property Types'!D:D,"Yes")
A9: Special Purpose | B9: =COUNTIF('Property Types'!A:A,A9) | C9: =COUNTIFS('Property Types'!A:A,A9,'Property Types'!D:D,"Yes")
A10: Self Storage | B10: =COUNTIF('Property Types'!A:A,A10) | C10: =COUNTIFS('Property Types'!A:A,A10,'Property Types'!D:D,"Yes")
A11: Manufactured Housing | B11: =COUNTIF('Property Types'!A:A,A11) | C11: =COUNTIFS('Property Types'!A:A,A11,'Property Types'!D:D,"Yes")
A12: Senior Living / Healthcare | B12: =COUNTIF('Property Types'!A:A,A12) | C12: =COUNTIFS('Property Types'!A:A,A12,'Property Types'!D:D,"Yes")
A13: Business for Sale | B13: =COUNTIF('Property Types'!A:A,A13) | C13: =COUNTIFS('Property Types'!A:A,A13,'Property Types'!D:D,"Yes")
A14: Note / Loan | B14: =COUNTIF('Property Types'!A:A,A14) | C14: =COUNTIFS('Property Types'!A:A,A14,'Property Types'!D:D,"Yes")
A15: TOTAL | B15: =SUM(B2:B14) | C15: =SUM(C2:C14)

Sheet Legend
A1: Column | B1: Description
A2: Main Type | B2: Crexi's top-level property category (Retail, Office, etc.)
A3: Subtype | B3: Specific sub-classification within the main type
A4: Slug | B4: URL-safe identifier suitable for code / routing
A5: Crexi Verified | B5: Yes = the slug was confirmed in a real Crexi URL during research
A6: Crexi URL | B6: Direct link to Crexi category page (verified slugs only)
A7: Notes | B7: Source commentary or cross-reference to other categories
A9: Legend
A10: Yes (green) | B10: Slug verified against a live Crexi URL
A11: No | B11: Standard industry subtype — Crexi may categorize these under the parent
